#VRML_SIM R2021a utf8
WorldInfo {
  coordinateSystem "NUE"
}
Viewpoint {
  orientation -0.990908724712669 -0.11806633010678295 -0.06449993010405475 1.0077039469200908
  position -0.05605282836097027 2.501952925928656 1.975169876078894
}
TexturedBackground {
}
RectangleArena {
  translation 0 -0.32 0
}
TexturedBackgroundLight {
}
Robot {
  translation 0.017324587607305663 -0.28190204302105604 0.018919407998058052
  rotation -0.7727446775407625 -0.0009317004887417097 0.6347163108559778 7.497960574182416e-06
  children [
    HingeJoint {
      jointParameters HingeJointParameters {
        position -8.346867136787062e-06
        axis -1 0 0
        anchor -0.045 -0.0176 0
      }
      device [
        RotationalMotor {
          name "motor roda direita"
        }
        PositionSensor {
          name "sensor roda direita"
        }
      ]
      endPoint Solid {
        translation 0.045206000000000066 -0.01814409292106674 0.08919090004318414
        rotation 0.9999872531608718 -0.0034687860966657077 0.003668928834181092 8.347257564443323e-06
        children [
          Transform {
            rotation 0 0 1 1.5707996938995747
            children [
              DEF shape_roda Shape {
                appearance PBRAppearance {
                  baseColor 0.8 0.15 0.3
                  roughness 1
                  metalness 0
                }
                geometry Cylinder {
                  height 0.01
                  radius 0.02
                }
              }
            ]
          }
        ]
        name "roda esquerda(3)"
        boundingObject Transform {
          rotation 0 0 1 1.5707996938995747
          children [
            DEF shape_roda Shape {
              appearance PBRAppearance {
                baseColor 0.8 0.15 0.3
                roughness 1
                metalness 0
              }
              geometry Cylinder {
                height 0.01
                radius 0.02
              }
            }
          ]
        }
        physics DEF fisica_roda Physics {
          density -1
          mass 0.005
        }
        linearVelocity -4.34134917080529e-09 9.81519780531967e-06 2.6688269103076813e-09
        angularVelocity 2.0716925386491345e-07 -1.0671877861870458e-09 2.2444851669009134e-07
      }
    }
    HingeJoint {
      jointParameters HingeJointParameters {
        position -8.293285294269698e-06
        axis -1 0 0
        anchor -0.045 -0.0176 0
      }
      device [
        RotationalMotor {
          name "motor roda direita"
        }
        PositionSensor {
          name "sensor roda direita"
        }
      ]
      endPoint Solid {
        translation -0.044794 -0.01814398814205398 0.08919090007232411
        rotation 0.9999870877085222 -0.003491225473254814 0.0036926631207319406 8.293617397454206e-06
        children [
          Transform {
            rotation 0 0 1 1.5707996938995747
            children [
              DEF shape_roda Shape {
                appearance PBRAppearance {
                  baseColor 0.8 0.15 0.3
                  roughness 1
                  metalness 0
                }
                geometry Cylinder {
                  height 0.01
                  radius 0.02
                }
              }
            ]
          }
        ]
        name "roda esquerda(2)"
        boundingObject Transform {
          rotation 0 0 1 1.5707996938995747
          children [
            DEF shape_roda Shape {
              appearance PBRAppearance {
                baseColor 0.8 0.15 0.3
                roughness 1
                metalness 0
              }
              geometry Cylinder {
                height 0.01
                radius 0.02
              }
            }
          ]
        }
        physics DEF fisica_roda Physics {
          density -1
          mass 0.005
        }
        linearVelocity -4.562024663999023e-09 9.82188565579849e-06 -1.7585670723727775e-09
        angularVelocity -9.458283819355927e-08 -6.865254686206891e-10 2.2441488018792856e-07
      }
    }
    HingeJoint {
      jointParameters HingeJointParameters {
        position -8.559310366678298e-06
        axis -1 0 0
        anchor -0.045 -0.0176 0
      }
      device [
        RotationalMotor {
          name "motor roda direita"
        }
        PositionSensor {
          name "sensor roda direita"
        }
      ]
      endPoint Solid {
        translation -0.044794 -0.018142256726658382 -0.09080910444141808
        rotation 0.9999878783274734 -0.003382654623636198 0.003577826968328237 8.55970223643523e-06
        children [
          Transform {
            rotation 0 0 1 1.5707996938995747
            children [
              DEF shape_roda Shape {
                appearance PBRAppearance {
                  baseColor 0.8 0.15 0.3
                  roughness 1
                  metalness 0
                }
                geometry Cylinder {
                  height 0.01
                  radius 0.02
                }
              }
            ]
          }
        ]
        name "roda esquerda(1)"
        boundingObject Transform {
          rotation 0 0 1 1.5707996938995747
          children [
            DEF shape_roda Shape {
              appearance PBRAppearance {
                baseColor 0.8 0.15 0.3
                roughness 1
                metalness 0
              }
              geometry Cylinder {
                height 0.01
                radius 0.02
              }
            }
          ]
        }
        physics DEF fisica_roda Physics {
          density -1
          mass 0.005
        }
        linearVelocity -4.6311127721034825e-09 9.804873775342872e-06 -2.1695226552462853e-09
        angularVelocity -9.452484465292563e-08 -6.645330214007172e-10 2.2441099334946069e-07
      }
    }
    HingeJoint {
      jointParameters HingeJointParameters {
        position -8.356940900284015e-06
        axis -1 0 0
        anchor -0.045 -0.0176 0
      }
      device [
        RotationalMotor {
          name "motor roda direita"
        }
        PositionSensor {
          name "sensor roda direita"
        }
      ]
      endPoint Solid {
        translation 0.04520599999999991 -0.0181423062925777 -0.09080909996242127
        rotation 0.9999872835353061 -0.003464650792394964 0.0036645548932954385 8.357253519551765e-06
        children [
          Transform {
            rotation 0 0 1 1.5707996938995747
            children [
              DEF shape_roda Shape {
                appearance PBRAppearance {
                  baseColor 0.8 0.15 0.3
                  roughness 1
                  metalness 0
                }
                geometry Cylinder {
                  height 0.01
                  radius 0.02
                }
              }
            ]
          }
        ]
        name "roda esquerda"
        boundingObject Transform {
          rotation 0 0 1 1.5707996938995747
          children [
            DEF shape_roda Shape {
              appearance PBRAppearance {
                baseColor 0.8 0.15 0.3
                roughness 1
                metalness 0
              }
              geometry Cylinder {
                height 0.01
                radius 0.02
              }
            }
          ]
        }
        physics DEF fisica_roda Physics {
          density -1
          mass 0.005
        }
        linearVelocity -4.418905903318522e-09 9.80045373504783e-06 -5.68609140679196e-09
        angularVelocity -3.65338869649065e-07 -3.1732470505407824e-10 2.2444126189638277e-07
      }
    }
    DEF rus_shape Shape {
      appearance PBRAppearance {
        baseColor 0.58 0.4 1
        roughness 1
        metalness 0
      }
      geometry Box {
        size 0.1 0.01 0.25
      }
    }
  ]
  name "rus"
  boundingObject DEF rus_shape Shape {
    appearance PBRAppearance {
      baseColor 0.58 0.4 1
      roughness 1
      metalness 0
    }
    geometry Box {
      size 0.1 0.01 0.25
    }
  }
  physics Physics {
    density -1
    mass 0.2
  }
  controller "meuRobo"
  synchronization FALSE
  linearVelocity -8.547292495931816e-09 9.82320380071878e-06 -3.434895560122682e-09
  angularVelocity -9.450245611247816e-08 -6.844447449060895e-10 2.244154976133152e-07
}
